//: Playground - noun: a place where people can play

//表示并抛出错误
//在 Swift 中，错误用符合Error协议的类型的值来表示。这个空协议表明该类型可以用于错误处理。

//Swift 的枚举类型尤为适合构建一组相关的错误状态，枚举的关联值还可以提供错误状态的额外信息。
enum VendingMachineError: Error {
    case invalidlSelection
    case insufficientFunds(coinsNeeded:Int)
    case outOfStock
}
// throw VendingMachineError.insufficientFunds(coinsNeeded: 5)

//处理错误
//Swift 中有4种处理错误的方式。你可以把函数抛出的错误传递给调用此函数的代码、用do-catch语句处理错误、将错误作为可选类型处理、或者断言此错误根本不会发生。

//用throwing函数传递错误
//一个 throwing 函数可以在其内部抛出错误，并将错误传递到函数被调用时的作用域。
//只有 throwing 函数可以传递错误。任何在某个非 throwing 函数内部抛出的错误只能在函数内部处理。

print("hhh")

struct Item {
    var price: Int
    var count: Int
}

class VendingMachine {
    var inventory = [
        "Candy Bar": Item(price: 12, count: 7),
        "Chips": Item(price: 10, count: 4),
        "Pretzels": Item(price: 7, count: 11)
    ]
    var coinsDeposited = 0
    func dispendeSnack(snack: String) {
        print("Dispensing \(snack)")
    }
    
    func vend(itemNamed name: String) throws {
        guard let item = inventory[name] else {
            throw VendingMachineError.invalidlSelection
        }
        guard item.count > 0 else {
            throw VendingMachineError.outOfStock
        }
        guard item.price <= coinsDeposited else {
            throw VendingMachineError.insufficientFunds(coinsNeeded: item.price - coinsDeposited)
        }
        
        coinsDeposited -= item.price
        var newItem = item
        newItem.count -= 1
        inventory[name] = newItem
        
        print("Dispensing \(name)")
    }
}
//因为vend(itemNamed:)方法会传递出它抛出的任何错误，在你的代码中调用此方法的地方，必须要么直接处理这些错误——使用do-catch语句，try?或try!；要么继续将这些错误传递下去。例如下面例子中，buyFavoriteSnack(_:vendingMachine:)同样是一个 throwing 函数，任何由vend(itemNamed:)方法抛出的错误会一直被传递到buyFavoriteSnack(person:vendingMachine:)函数被调用的地方。
let favoriteSnacks = [
    "Alice": "Chips",
    "Bob": "Licorice",
    "Eve": "Pretzels",
]
func buyFavoriteSnack(person: String, vendingMachine: VendingMachine) throws {
    let snackName = favoriteSnacks[person] ?? "Candy Bar"
    try vendingMachine.vend(itemNamed: snackName)
}
//buyFavoriteSnack(person:vendingMachine:)函数会查找某人最喜欢的零食，并通过调用vend(itemNamed:)方法来尝试为他们购买。因为vend(itemNamed:)方法能抛出错误，所以在调用的它时候在它前面加了try关键字。
//throwing构造器能像throwing函数一样传递错误
struct PurchasedSnack {
    let name: String
    init(name: String, vendingMachine: VendingMachine) throws {
        try vendingMachine.vend(itemNamed: name)
        self.name = name
    }
}

//用Do-Catch处理错误
//可以使用一个do-catch语句运行一段闭包代码来处理错误。如果在do子句中的代码抛出了一个错误，这个错误会与catch子句做匹配，从而决定哪条子句能处理它。
//catch子句不必将do子句中的代码所抛出的每一个可能的错误都作处理。如果所有catch子句都未处理错误，错误就会传递到周围的作用域。然而，错误还是必须要被某个周围的作用域处理的——要么是一个外围的do-catch错误处理语句，要么是一个 throwing 函数的内部。举例来说，下面的代码处理了VendingMachineError枚举类型的全部枚举值，但是所有其它的错误就必须由它周围的作用域处理：
var vendingMacine = VendingMachine()
vendingMacine.coinsDeposited = 8
do {
    try buyFavoriteSnack(person: "Alice", vendingMachine: vendingMacine)
} catch VendingMachineError.outOfStock {
    print("Out of Stock")
} catch VendingMachineError.invalidlSelection {
    print("Invalid Selection")
} catch VendingMachineError.insufficientFunds(let coinsNeed) {
    print("Insufficient funds. Please insert an additional \(coinsNeed) coins")
}

//将错误转换成可选值
func someThrowingFunction() throws -> Int {
    // 假设有个return 0
    return 0
}

let x = try? someThrowingFunction()

let y: Int?
do {
    y = try someThrowingFunction()
} catch {
    y = nil
}
//如果someThrowingFunction()抛出一个错误，x和y的值是nil。否则x和y的值就是该函数的返回值。注意，无论someThrowingFunction()的返回值类型是什么类型，x和y都是这个类型的可选类型。例子中此函数返回一个整型，所以x和y是可选整型。


//禁用错误传递
///有时你知道某个throwing函数实际上在运行时是不会抛出错误的，在这种情况下，你可以在表达式前面写try!来禁用错误传递，这会把调用包装在一个不会有错误抛出的运行时断言中。如果真的抛出了错误，你会得到一个运行时错误。
//let photo = try! loadImage(atPath: "./Resources/John Appleseed.jpg")

//指定清理操作
//可以使用defer语句在即将离开当前代码块时执行一系列语句。该语句让你能执行一些必要的清理工作，不管是以何种方式离开当前代码块的——无论是由于抛出错误而离开，还是由于诸如return或者break的语句。例如，你可以用defer语句来确保文件描述符得以关闭，以及手动分配的内存得以释放

//defer语句将代码的执行延迟到当前的作用域退出之前。该语句由defer关键字和要被延迟执行的语句组成。延迟执行的语句不能包含任何控制转移语句，例如break或是return语句，或是抛出一个错误。延迟执行的操作会按照它们被指定时的顺序的相反顺序执行——也就是说，第一条defer语句中的代码会在第二条defer语句中的代码被执行之后才执行，以此类推

//func processFile(filename: String) throws {
//    if exists(filename) {
//        let file = open(filename)
//        defer {
//            close(file)
//        }
//        while let line = try file.readline() {
//        
//        }
//        // close(file) 会在这里被调用，即作用域的最后。
//    }
//}



